<mujoco model="n_joint_branch">
  <option gravity="0 0 -10"/>
  <option integrator="RK4"/>
  <compiler angle="radian"/>
  <compiler inertiafromgeom="auto"/>

  <visual>
    <headlight diffuse="0.5 0.5 0.5" specular="1 1 1"/>
  </visual>

  <asset>
    <texture type="skybox" builtin="gradient" rgb1=".5 .5 .5" rgb2="0 0 0" width="10" height="10"/>
    <texture type="2d" name="groundplane" builtin="checker" mark="edge" rgb1="1 1 1" rgb2="1 1 1" markrgb="0 0 0" width="300" height="300"/>
    <material name="groundplane" texture="groundplane" texuniform="true" texrepeat="5 5" reflectance="0.3"/>
  </asset>

  <worldbody>
    <geom name="floor" size="5 5 0.01" type="plane" material="groundplane"/>
    <light pos="0 -.5 3" diffuse=".5 .5 .5" specular=".5 .5 .5" castshadow="false"/>

    <!-- probe -->
    <body name="probe_link" pos="-0.107 0 .75">
      <inertial pos="0.0801087 0 0" quat="0 0.707107 0 0.707107" mass="0.115" diaginertia="0.0230877 0.0230846 0.0230031"/>
      <joint name="probe_joint" pos="0 0 0" axis="1 0 0" type="slide" range="0 0.045"/>
      <geom size="0.005 0.075" pos="0.025 0 0" quat="0.707107 0 0.707106 0" type="cylinder" rgba="0 1 0 1"/>
    </body>

    <!-- tiny blue box -->
    <body name="branch_base" pos="0 0 0">
      <geom size="0.025 0.025 0.025" type="box" rgba="0 0 1 1"/>
    </body>
     
  </worldbody>

  <actuator>
    <motor name="probe_motor" joint="probe_joint" forcerange="-10 10"/>
  </actuator>

</mujoco>
