<mujoco model="n_joint_branch">
  <option gravity="0 0 -10"/>
  <option integrator="RK4"/>
  <compiler angle="radian"/>
  <compiler inertiafromgeom="auto"/>
  <statistic center="0 0 0.35" />

  <visual>
    <headlight diffuse=".9 .9 .9" specular=".75 .75 .75"/>
    <global orthographic="false" fovy="45" elevation="-15" />
    <!-- <map fogstart="2" fogend="8" />
    <rgba fog="1 1 1 1"/> -->
  </visual>

  <asset>
    <!-- blue sky -->
    <!-- <texture type="skybox" builtin="gradient" rgb1="0 .38 .6" rgb2="0 .71 .89" width="5" height="2"/> -->
    <!-- "agreeable gray" background -->
    <!-- <texture type="skybox" builtin="gradient" rgb1=".82 .82 .76"  rgb2=".82 .82 .76" width="5" height="2"/> -->
    <!-- "ash gray" background -->
    <!-- <texture type="skybox" builtin="gradient" rgb1=".70 .75 .71"  rgb2=".70 .75 .71" width="5" height="2"/> -->
    <!-- "chrome" background -->
    <texture type="skybox" builtin="gradient" rgb1=".86 .89 .91"  rgb2=".86 .89 .91" width="5" height="2"/>
    <texture type="2d" name="groundplane" builtin="checker" mark="edge" rgb1="1 1 1" rgb2="1 1 1" markrgb="0 0 0" width="300" height="300"/>
    <material name="groundplane" texture="groundplane" texuniform="true" texrepeat="5 5" reflectance="0.01"/>
  </asset>

  <worldbody>
    <!-- <camera name="free_cam" pos="-.034 -1.406 1.568" quat="0.92388 0 0.38268 0"/>  -->
    <!-- <geom name="floor" size="0.5 0.5 0.01" type="plane" rgba="0 0.6 0.09 1"/> -->
    <geom name="floor" size="0.25 0.25 0.01" type="plane" material="groundplane"/>
    <light pos="0 -.5 3" diffuse=".6 .6 .6" specular=".6 .6 .6" castshadow="false" />
    <!-- <light pos="0 -2 0.5" mode="targetbody" target="probe_link" diffuse=".6 .6 .6" specular="0 0 0" castshadow="false"/> -->

    <!-- probe -->
    <body name="probe_link" pos="-0.107 0 .75">
      <inertial pos="0.0801087 0 0" quat="0 0.707107 0 0.707107" mass="0.115" diaginertia="0.0230877 0.0230846 0.0230031"/>
      <joint name="probe_joint" pos="0 0 0" axis="1 0 0" type="slide" range="0 0.045"/>
      <geom size="0.005 0.075" pos="0.025 0 0" quat="0.707107 0 0.707106 0" type="cylinder" rgba="0 1 0 1"/>
    </body>

    <!-- tiny blue box -->
    <body name="branch_base" pos="0 0 0">
      <!-- <geom size="0.025 0.025 0.025" type="box" rgba="0 0 1 1"/> -->
    </body>
     
  </worldbody>

  <actuator>
    <motor name="probe_motor" joint="probe_joint" forcerange="-10 10"/>
  </actuator>

</mujoco>
